Don't panic!
================================================================================

![Don't panic! This is fine.](images/this-is-fine.webp)

Panic!
--------------------------------------------------------------------------------

In Lean, we can use `panic!` to signal an error and exit the program with a message:

```lean
def pred (n : Nat) : Nat :=
  if n > 0 then
    n - 1
  else
    panic! "No pred for 0"
```

```lean
#eval pred 7
6
```

```lean
#eval pred 0
PANIC at pred ...: No pred for 0
...
```

Similarly, panic can be used for example in the `IO` context:

```lean
def kthxbye : IO Unit := do
  IO.println "OK, thanks"
  panic! "bye!"
```

In the Lean standard library, `panic!` is for example raised to access an element of a list at index which may be out ouf bounds.
When `arr` is a collection of elements of type `elem`, the syntax `arr[i]!` 
returns the i'th element of the collection if the index is within the collection
bounds, or otherwise -- returns the default term from `Inhabited elem` for type-checking purposes and effectively -- panics at runtime.


```lean
def a := [1, 2, 3]

#eval a[0]!
-- 0

#eval a[42]!
-- PANIC at _private.Init.GetElem.0.List.get!Internal ...: invalid index
-- ...
```

The signature of `getElem!` is:

```lean

The syntax is actually a shortcut for `getElem!`:

```lean
#eval a.getElem! 0
-- 0  

#eval a.getElem! 42
PANIC at _private.Init.GetElem.0.List.get!Internal Init.GetElem:325:18: invalid index
```


Not that there is no way to recover from a panic, so it is best to use it
only for situations that are truly unrecoverable (or as a temporary measure
in prototyping).

### Do not mess with the type checker

Lean does not suspend the type checker when evaluating `panic!`. 
Instead, it follows the following compile-time rule:

> panic! msg formally evaluates to @Inhabited.default Î± if the expected type Î± 
> implements Inhabited. 

And later:

> At runtime, msg and the file position are printed to stderr unless the C
> function lean_set_panic_messages(false) has been executed before. 
> If the C function lean_set_exit_on_panic(true) has been executed before, 
> the process is then aborted.

So our `pred` function is typechecked as if it returned a default value of the

```lean
#eval (default : Nat)
0
```

So the `pred` function is effectively typechecked as: 

```lean
def pred (n : Int) : Int :=
  if n > 0 then
    n - 1
  else
    0
```

So effectively, you cannot used `panic!` instead of a type which has not declared
a default value. Hopefully, Lean declares default values for most types; 
but it cannot do anything for `Empty` for example

```lean
inductive Nat' where
  | zero : Nat'
  | succ (n : Nat') : Nat'


def fail : Nat' :=
  panic! "Nope"
```


```lean
instance : Inhabited Nat' where
  default := Nat'.zero

def fail' : Nat' :=
  panic! "Nope"
```

You can also let Lean automatically select a default value for you:

```lean
inductive Nat' where
  | zero : Nat'
  | succ (n : Nat') : Nat'
  deriving Inhabited
```

### TODO: what's going on with `IO`?

**Fails** with:
```lean
ðŸ”´ #eval (default : IO Unit)
(`Inhabited.default` for `IO.Error`)
```

**Succeeds** with:
```lean
ðŸŸ¢ #eval (default : IO.Error)
(`Inhabited.default` for `IO.Error`)
```



----

The Python closest equivalent of `panic!` in Python is `sys.exit()`. 

```python
import sys
```

```python
sys.exit("ðŸ‘‹")
ðŸ‘‹
``` 

So even if you try to catch all the types of exceptions, you will not manage to catch the exit call; the code

```python
try:
    sys.exit("ðŸ‘‹")
except Exception:
    print("ðŸ›‘")
```

will fail and print ðŸ‘‹.

### Details

Actually, `sys.exit()` raises a `SystemExit` exception, which is a subclass of `BaseException`, not `Exception`. This is why the above code does not catch it.
But you can still catch it with:

```python
try:
    sys.exit("ðŸ‘‹")
except SystemExit as e:
    print("ðŸ›‘")
```
 or with a bare except:

```python
try:
    sys.exit("ðŸ‘‹")
except:
    print("ðŸ›‘")
```

Both these code snippers will succeed and print ðŸ›‘.


Option
--------------------------------------------------------------------------------

```lean
def getCoords (string : String) : Option (Nat Ã— Nat) :=
  let parts := string.splitOn " "
  let xy_str := match parts[0]? with
  | none => none
  | some x => match parts[1]? with
    | none => none
    | some y => some (x, y)
  match xy_str with
  | none => none
  | some (x, y) => match x.toNat? with
    | none => none
    | some x' => match y.toNat? with
      | none => none
      | some y' => some (x', y')

#eval getCoords "3 4"
-- some (3, 4)

#eval getCoords "douze quarante-deux"
-- none
```

Imperative style with the `do` block:

```lean
def getCoords' (string : String) : Option (Nat Ã— Nat) := do
  let parts := string.splitOn " "
  let x_str <- parts[0]?
  let y_str <- parts[1]?
  let x <- x_str.toNat?
  let y <- y_str.toNat?
  return (x, y)

#eval getCoords' "3 4"
-- some (3, 4)

#eval getCoords' "douze quarante-deux"
-- none
```

As a monad, `Option`:

  - lifts an element `a : `Î±` to `some a : Option Î±`,

  - chains operations by returning the first `Option.none` which
    occurs, or `some` of the final result if all operations succeed.

```lean
def pure : Î± â†’ Option Î± := Option.some

def bind : Option Î± â†’ (Î± â†’ Option Î²) â†’ Option Î²
  | none,   _ => none
  | some a, f => f a
```




Except
--------------------------------------------------------------------------------

ðŸš§ **TODO**
   
   - Except as an enhanced `Option` with an error message

   - JSON example

   - try catch syntax (instantiate `MonadExcept`)

 IO
 ----------------------------

   - instantiate MonadExcept (try catch syntax)

   - list / use "POSIX"-like error set

   - custom error types with IO (EIO and replace `IO.Error` with custom error type)
